Workbook

Sheet Read me
A1: Amp Academy — Enterprise Proforma & Equity Model
A2: Prepared for Jim Repasch & Mike Longley · 2026-06-21 · companion to the Business Plan
A4: ⚠ THIS IS ILLUSTRATIVE — NOT FINANCIAL OR LEGAL ADVICE.
A5: These are conservative, ground-up projections on TINY market acceptance (one customer at a time). They are a planning tool to size the opportunity and the equity trade — not a forecast or a promise. Actual results will differ. Entity, vesting, buy-sell, salaries, and distributions must be finalized by an attorney + CPA.
A7: How to use it
A8: • Blue cells are inputs — change them to run your own scenario. • Black cells are formulas. • Green cells pull from another tab. • Yellow = key assumption to confirm.
A10: The tabs
A11: 1) Proforma (5-yr) — the ground-up P&L and cash: Customer #1 → #50, revenue, costs, commissions, what's left to distribute.
A12: 2) Infrastructure (free→paid) — exactly where AA rides on third-party FREE tiers today, the real market price of each, and the AA revenue mark where each flips from free to paid. Honest-state: nothing is free forever.
A13: 3) Equity & vesting — both cap-table scenarios, the vesting/forfeiture rules, and each person's stake VALUE and CASH at every milestone. This is the 'quantify it for me.'
A15: The doctrine baked in
A16: • Nobody rides for free — equity is milestone-EARNED (start month 1, 12-month cliff, forfeit if you leave before month 13).
... A19: • Enterprise is the engine; Perry/consumer is a SEPARATE play (its own model).

Sheet Proforma (5-yr)
A1: Amp Academy — Enterprise Proforma (ground-up, tiny acceptance)
A2: All figures illustrative · enterprise/institutional only · USD
A4: ASSUMPTIONS (blue = edit me)
A5: Driver | B5: Note | C5: Y1 | D5: Y2 | E5: Y3 | F5: Y4 | G5: Y5
A6: Customers (cumulative, end of yr) | B6: the ramp | C6: 1 | D6: 5 | E6: 12 | F6: 25 | G6: 50
A7: New customers added | B7: derived | C7: =C6 -> 1 | D7: =D6-C6 -> 4 | E7: =E6-D6 -> 7 | F7: =F6-E6 -> 13 | G7: =G6-F6 -> 25
A8: Eff. annual revenue / customer ($) | B8: blended 1-yr & 3-yr | C8: 4000 | D8: 4000 | E8: 4000 | F8: 4000 | G8: 4000
A9: 1-yr list ACV ($) — for commissions | B9: CA-style | C9: 4500 | D9: 4500 | E9: 4500 | F9: 4500 | G9: 4500
A10: Students / customer (avg) | B10: cohort size | C10: 25 | D10: 25 | E10: 25 | F10: 25 | G10: 25
A11: Tutor API cost / student / yr ($) | B11: Anthropic usage | C11: 0.5 | D11: 0.5 | E11: 0.5 | F11: 0.5 | G11: 0.5
A12: Fixed infrastructure / yr ($) | B12: see Infrastructure tab | C12: 600 | D12: 900 | E12: 1500 | F12: 3000 | G12: 6000
A13: Commission MOST / LESS / LEAST (%) | B13: yr1 / yr2 / yr3 of deal | C13: 20%/10%/5% | H13: MOST | I13: 0.2
H14: LESS | I14: 0.1
H15: LEAST | I15: 0.05
A16: LUKAS_APPS license (% of revenue) | B16: $0 until Y2, then on | C16: 0 | D16: 0.1 | E16: 0.1 | F16: 0.1 | G16: 0.1
A17: Legal / trademark / entity (one-time) | B17: Y1 setup | C17: 6000 | D17: 0 | E17: 0 | F17: 0 | G17: 0
A18: CPA / admin / yr ($) | C18: 1500 | D18: 1500 | E18: 2000 | F18: 2500 | G18: 3000
A19: Salaries / yr ($) — cashflow-gated | B19: starts when cash supports | C19: 0 | D19: 0 | E19: 18000 | F19: 48000 | G19: 90000
A20: Marketing / PostMind / tools / yr ($) | B20: organic-led | C20: 1200 | D20: 2400 | E20: 4800 | F20: 7200 | G20: 9600
A21: Operating reserve target ($) | B21: leave to operate | C21: 5000 | D21: 8000 | E21: 12000 | F21: 18000 | G21: 25000
A22: Valuation multiple (x ARR) | B22: illustrative, early-stage | C22: 3 | D22: 3 | E22: 3 | F22: 3 | G22: 3
A24: PROFORMA P&L → cash to owners
A25: Line ($) | C25: Y1 | D25: Y2 | E25: Y3 | F25: Y4 | G25: Y5
A26: Enterprise revenue | C26: =C6*C8 -> 4000 | D26: =D6*D8 -> 20000 | E26: =E6*E8 -> 48000 | F26: =F6*F8 -> 100000 | G26: =G6*G8 -> 200000
A27: Tutor API (usage) | C27: =-C6*C10*C11 -> -12.5 | D27: =-D6*D10*D11 -> -62.5 | E27: =-E6*E10*E11 -> -150 | F27: =-F6*F10*F11 -> -312.5 | G27: =-G6*G10*G11 -> -625
A28: Fixed infrastructure | C28: =-C12 -> -600 | D28: =-D12 -> -900 | E28: =-E12 -> -1500 | F28: =-F12 -> -3000 | G28: =-G12 -> -6000
A29: Gross profit | C29: =C26+C27+C28 -> 3387.5 | D29: =D26+D27+D28 -> 19037.5 | E29: =E26+E27+E28 -> 46350 | F29: =F26+F27+F28 -> 96687.5 | G29: =G26+G27+G28 -> 193375
A30: Gross margin % | C30: =IF(C26=0,0,C29/C26) -> 0.846875 | D30: =IF(D26=0,0,D29/D26) -> 0.951875 | E30: =IF(E26=0,0,E29/E26) -> 0.965625 | F30: =IF(F26=0,0,F29/F26) -> 0.966875 | G30: =IF(G26=0,0,G29/G26) -> 0.966875
A31: Commissions (MOST/LESS/LEAST) | C31: =-(C7*C9)*$I$13 -> -900 | D31: =-(D7*D9)*$I$13-(C7*C9)*$I$14 -> -4050 | E31: =-(E7*E9)*$I$13-(D7*D9)*$I$14-(C7*C9)*$I$15 -> -8325 | F31: =-(F7*F9)*$I$13-(E7*E9)*$I$14-(D7*D9)*$I$15 -> -15750 | G31: =-(G7*G9)*$I$13-(F7*F9)*$I$14-(E7*E9)*$I$15 -> -29925
A32: LUKAS_APPS license | C32: =-C26*C16 -> 0 | D32: =-D26*D16 -> -2000 | E32: =-E26*E16 -> -4800 | F32: =-F26*F16 -> -10000 | G32: =-G26*G16 -> -20000
A33: Legal / TM / entity | C33: =-C17 -> -6000 | D33: =-D17 -> 0 | E33: =-E17 -> 0 | F33: =-F17 -> 0 | G33: =-G17 -> 0
A34: CPA / admin | C34: =-C18 -> -1500 | D34: =-D18 -> -1500 | E34: =-E18 -> -2000 | F34: =-F18 -> -2500 | G34: =-G18 -> -3000
A35: Salaries (cashflow-gated) | C35: =-C19 -> 0 | D35: =-D19 -> 0 | E35: =-E19 -> -18000 | F35: =-F19 -> -48000 | G35: =-G19 -> -90000
A36: Marketing / tools | C36: =-C20 -> -1200 | D36: =-D20 -> -2400 | E36: =-E20 -> -4800 | F36: =-F20 -> -7200 | G36: =-G20 -> -9600
A37: Operating cash flow | C37: =C29+C31+C32+C33+C34+C35+C36 -> -6212.5 | D37: =D29+D31+D32+D33+D34+D35+D36 -> 9087.5 | E37: =E29+E31+E32+E33+E34+E35+E36 -> 8425 | F37: =F29+F31+F32+F33+F34+F35+F36 -> 13237.5 | G37: =G29+G31+G32+G33+G34+G35+G36 -> 40850
A38: less: reserve build to target | C38: =-C21 -> -5000 | D38: =-(D21-C21) -> -3000 | E38: =-(E21-D21) -> -4000 | F38: =-(F21-E21) -> -6000 | G38: =-(G21-F21) -> -7000
A39: Distributable to owners | C39: =MAX(0,C37+C38) -> 0 | D39: =MAX(0,D37+D38) -> 6087.5 | E39: =MAX(0,E37+E38) -> 4425 | F39: =MAX(0,F37+F38) -> 7237.5 | G39: =MAX(0,G37+G38) -> 33850
A40: Cumulative distributed | C40: =C39 -> 0 | D40: =C40+D39 -> 6087.5 | E40: =D40+E39 -> 10512.5 | F40: =E40+F39 -> 17750 | G40: =F40+G39 -> 51600
A41: ARR (recurring revenue) | C41: =C26 -> 4000 | D41: =D26 -> 20000 | E41: =E26 -> 48000 | F41: =F26 -> 100000 | G41: =G26 -> 200000
A42: Implied enterprise value (ARR×mult) | C42: =C41*C22 -> 12000 | D42: =D41*D22 -> 60000 | E42: =E41*E22 -> 144000 | F42: =F41*F22 -> 300000 | G42: =G41*G22 -> 600000
...

Sheet Infrastructure (free→paid)
A1: Amp Academy — what we ride for free today, and when it costs
A2: Honest-state for Reppy & Longley: nothing is free forever. Here's each third-party service, its real market price, and the AA revenue mark where it flips from free to paid.
A4: Service | B4: What it does for AA | C4: Today | D4: Market price (paid) | E4: Flips to paid when…
A5: GitHub Pages | B5: Hosts the Campus + all course apps | C5: FREE (public repos) | D5: $0 (stays free) | E5: Effectively never at our scale (soft ~100GB bandwidth/mo)
A6: Cloudflare Workers | B6: Runs the AI tutor relay | C6: FREE (≤100k req/day) | D6: $5/mo (Workers Paid) | E6: Daily tutor calls exceed ~100k — i.e., several thousand active students
A7: Supabase (edex) | B7: Roster, entitlement, certificates DB | C7: PRO $25/mo (already paying) | D7: $25/mo → $599/mo (Team) | E7: Team tier only at thousands of seats / org-level controls
A8: Anthropic API | B8: The tutor's brain (every Q&A) | C8: Usage-based (pay per call) | D8: ≈$0.003–0.01 / question | E8: Always usage — ≈$0.50/student/course; the price already covers it
A9: Email (auth/magic-link) | B9: Sign-in + notifications | C9: FREE tier | D9: ≈$20/mo (e.g., Resend) | E9: Monthly signups exceed the free tier (a few thousand/mo)
A10: Domain (amp-academy.com) | B10: The front door | C10: Owned (Longley holds) | D10: ≈$15/yr | E10: Already owned — annual renewal only
A12: Bottom line: AA's cost base is genuinely tiny and software-high-margin. The only cost that scales with use is the tutor API (~$0.50/student/course) — and pricing already covers it. Fixed SaaS stays under a few hundred $/yr until we're at thousands of seats.

Sheet Equity & vesting
A1: Amp Academy — Equity, vesting & what each stake is worth
A2: Two scenarios, side by side · values illustrative (EV = ARR × multiple from Proforma tab)
A4: THE RULES (everyone, same)
A5: • Vesting starts month 1; nothing exercisable before month 13 (12-month cliff).
A6: • Leave before month 13 → total forfeiture. After month 13 → keep VESTED, forfeit UNVESTED (returns to pool); buy-back at fair value (good leaver) / lower-of-cost-or-FMV (bad leaver).
A7: • Vesting is milestone-EARNED: still working + pursuing deals + generating revenue + hitting defined goals. Full vest over 3 years.
A8: • Distributions: quarterly sweep to VESTED holders, pro-rata, after operating reserve + obligations + tax set-aside. Most cash to owners.
A11: SCENARIO A — HEADLINE: give more (LOCKED 2026-06-21)
A12: Holder | B12: Equity % | C12: Milestone to earn it
A13: Michael Lukas | B13: 0.65 | C13: Tech + platform license + ongoing build (principal); 52% fully loaded
A14: Jim Repasch | B14: 0.16 | C14: Customer #1 (BASD/VOTECH) → then #5 → #12 (tranches)
A15: Mike Longley | B15: 0.16 | C15: SME content + relationships + his closes (tranches)
A16: Jimmy Christmas | B16: 0.03 | C16: IBEW deals he closes (up to 3% over 3 yrs)
A17: Total | B17: =SUM(B13:B16) -> 1
A19: SCENARIO B — Egalitarian (30/30/30)
A20: Holder | B20: Equity % | C20: Milestone to earn it
A21: Michael Lukas | B21: 0.37 | C21: Tech + platform license + ongoing build (founder)
A22: Jim Repasch | B22: 0.3 | C22: Customer #1 (BASD/VOTECH) → then #5 → #12 (tranches)
A23: Mike Longley | B23: 0.3 | C23: SME content + relationships + his closes (tranches)
A24: Jimmy Christmas | B24: 0.03 | C24: IBEW deals he closes (up to 3% over 3 yrs)
A25: Total | B25: =SUM(B21:B24) -> 1
A28: WHAT EACH STAKE IS WORTH (fully-vested basis; EV from Proforma)
A29: Holder / scenario | C29: Y1 | D29: Y2 | E29: Y3 | F29: Y4 | G29: Y5
A30: Scenario A — equity value
A31: Michael | C31: ='Proforma (5-yr)'!C42*B13 -> 7800 | D31: ='Proforma (5-yr)'!D42*B13 -> 39000 | E31: ='Proforma (5-yr)'!E42*B13 -> 93600 | F31: ='Proforma (5-yr)'!F42*B13 -> 195000 | G31: ='Proforma (5-yr)'!G42*B13 -> 390000
A32: Repasch | C32: ='Proforma (5-yr)'!C42*B14 -> 1920 | D32: ='Proforma (5-yr)'!D42*B14 -> 9600 | E32: ='Proforma (5-yr)'!E42*B14 -> 23040 | F32: ='Proforma (5-yr)'!F42*B14 -> 48000 | G32: ='Proforma (5-yr)'!G42*B14 -> 96000
A33: Longley | C33: ='Proforma (5-yr)'!C42*B15 -> 1920 | D33: ='Proforma (5-yr)'!D42*B15 -> 9600 | E33: ='Proforma (5-yr)'!E42*B15 -> 23040 | F33: ='Proforma (5-yr)'!F42*B15 -> 48000 | G33: ='Proforma (5-yr)'!G42*B15 -> 96000
A34: Jimmy | C34: ='Proforma (5-yr)'!C42*B16 -> 360 | D34: ='Proforma (5-yr)'!D42*B16 -> 1800 | E34: ='Proforma (5-yr)'!E42*B16 -> 4320 | F34: ='Proforma (5-yr)'!F42*B16 -> 9000 | G34: ='Proforma (5-yr)'!G42*B16 -> 18000
A35: Scenario B — equity value
A36: Michael | C36: ='Proforma (5-yr)'!C42*B21 -> 4440 | D36: ='Proforma (5-yr)'!D42*B21 -> 22200 | E36: ='Proforma (5-yr)'!E42*B21 -> 53280 | F36: ='Proforma (5-yr)'!F42*B21 -> 111000 | G36: ='Proforma (5-yr)'!G42*B21 -> 222000
A37: Repasch | C37: ='Proforma (5-yr)'!C42*B22 -> 3600 | D37: ='Proforma (5-yr)'!D42*B22 -> 18000 | E37: ='Proforma (5-yr)'!E42*B22 -> 43200 | F37: ='Proforma (5-yr)'!F42*B22 -> 90000 | G37: ='Proforma (5-yr)'!G42*B22 -> 180000
A38: Longley | C38: ='Proforma (5-yr)'!C42*B23 -> 3600 | D38: ='Proforma (5-yr)'!D42*B23 -> 18000 | E38: ='Proforma (5-yr)'!E42*B23 -> 43200 | F38: ='Proforma (5-yr)'!F42*B23 -> 90000 | G38: ='Proforma (5-yr)'!G42*B23 -> 180000
A39: Jimmy | C39: ='Proforma (5-yr)'!C42*B24 -> 360 | D39: ='Proforma (5-yr)'!D42*B24 -> 1800 | E39: ='Proforma (5-yr)'!E42*B24 -> 4320 | F39: ='Proforma (5-yr)'!F42*B24 -> 9000 | G39: ='Proforma (5-yr)'!G42*B24 -> 18000
A41: CUMULATIVE CASH TO OWNERS (the distribution sweep)
A42: Holder / scenario | C42: Y1 | D42: Y2 | E42: Y3 | F42: Y4 | G42: Y5
A43: Scenario A — cash
A44: Michael | C44: ='Proforma (5-yr)'!C40*B13 -> 0 | D44: ='Proforma (5-yr)'!D40*B13 -> 3956.875 | E44: ='Proforma (5-yr)'!E40*B13 -> 6833.125 | F44: ='Proforma (5-yr)'!F40*B13 -> 11537.5 | G44: ='Proforma (5-yr)'!G40*B13 -> 33540
A45: Repasch | C45: ='Proforma (5-yr)'!C40*B14 -> 0 | D45: ='Proforma (5-yr)'!D40*B14 -> 974 | E45: ='Proforma (5-yr)'!E40*B14 -> 1682 | F45: ='Proforma (5-yr)'!F40*B14 -> 2840 | G45: ='Proforma (5-yr)'!G40*B14 -> 8256
A46: Longley | C46: ='Proforma (5-yr)'!C40*B15 -> 0 | D46: ='Proforma (5-yr)'!D40*B15 -> 974 | E46: ='Proforma (5-yr)'!E40*B15 -> 1682 | F46: ='Proforma (5-yr)'!F40*B15 -> 2840 | G46: ='Proforma (5-yr)'!G40*B15 -> 8256
A47: Jimmy | C47: ='Proforma (5-yr)'!C40*B16 -> 0 | D47: ='Proforma (5-yr)'!D40*B16 -> 182.625 | E47: ='Proforma (5-yr)'!E40*B16 -> 315.375 | F47: ='Proforma (5-yr)'!F40*B16 -> 532.5 | G47: ='Proforma (5-yr)'!G40*B16 -> 1548
...

Sheet Exit & $1M goal
A1: Amp Academy — the Exit & the $1M-each goal
A2: Owner's goal: net ~$1,000,000 EACH to Repasch & Longley at a sale. The tiny-acceptance floor (Y5: $200k ARR, $600k EV) is PROOF OF LIFE — not the payday. The payday is a strategic roll-up after SCALING (Holt + more cohorts). Pre-tax, illustrative, not advice.
A4: 1) SENSITIVITY — net proceeds to ONE partner (= exit value × their %)
A5: Exit valuation ↓ / equity % → | B5: 0.15 | C5: 0.2 | D5: 0.25 | E5: 0.3
A6: 3000000 | B6: =$A6*B$5 -> 450000 | C6: =$A6*C$5 -> 600000 | D6: =$A6*D$5 -> 750000 | E6: =$A6*E$5 -> 900000
A7: 4000000 | B7: =$A7*B$5 -> 600000 | C7: =$A7*C$5 -> 800000 | D7: =$A7*D$5 -> 1000000 | E7: =$A7*E$5 -> 1200000
A8: 5000000 | B8: =$A8*B$5 -> 750000 | C8: =$A8*C$5 -> 1000000 | D8: =$A8*D$5 -> 1250000 | E8: =$A8*E$5 -> 1500000
A9: 8000000 | B9: =$A9*B$5 -> 1200000 | C9: =$A9*C$5 -> 1600000 | D9: =$A9*D$5 -> 2000000 | E9: =$A9*E$5 -> 2400000
A10: 12000000 | B10: =$A10*B$5 -> 1800000 | C10: =$A10*C$5 -> 2400000 | D10: =$A10*D$5 -> 3000000 | E10: =$A10*E$5 -> 3600000
A11: 15000000 | B11: =$A11*B$5 -> 2250000 | C11: =$A11*C$5 -> 3000000 | D11: =$A11*D$5 -> 3750000 | E11: =$A11*E$5 -> 4500000
A12: ≈ $1M each lands around: 16% at ~$6.25M (KEEPS Michael's 52% majority) · 20% at $5M (Michael falls to 44% fully loaded — loses control) · 15% at ~$6.7M.
A14: 2) HOW BIG IT MUST GET — required ARR for each exit (and cohorts @ $4k)
A15: Exit valuation | B15: ARR @ 3.0x | C15: ARR @ 4.0x | D15: ARR @ 5.0x | E15: Cohorts @4x ($4k each)
A16: 3000000 | B16: =A16/3 -> 1000000 | C16: =A16/4 -> 750000 | D16: =A16/5 -> 600000 | E16: =C16/4000 -> 187.5
A17: 5000000 | B17: =A17/3 -> 1666666.7 | C17: =A17/4 -> 1250000 | D17: =A17/5 -> 1000000 | E17: =C17/4000 -> 312.5
A18: 8000000 | B18: =A18/3 -> 2666666.7 | C18: =A18/4 -> 2000000 | D18: =A18/5 -> 1600000 | E18: =C18/4000 -> 500
A19: 12000000 | B19: =A19/3 -> 4000000 | C19: =A19/4 -> 3000000 | D19: =A19/5 -> 2400000 | E19: =C19/4000 -> 750
A20: Reality check: $5M exit ≈ $1.25M ARR ≈ ~310 cohorts (or far fewer big-district deals). That's the Holt-powered growth case — well above the tiny-acceptance floor.
A22: 3) THE 'GIVE MORE' SPLIT — take at a target exit
A23: Target exit value ($) — edit me | B23: 6250000
A24: Holder | B24: Equity % | C24: Net at target exit
A25: Michael Lukas (principal, fully loaded) | B25: 0.52 | C25: =B25*$B$23 -> 3250000
A26: Jim Repasch | B26: 0.16 | C26: =B26*$B$23 -> 1000000
A27: Mike Longley | B27: 0.16 | C27: =B27*$B$23 -> 1000000
A28: Mike Holt — CCO (if he joins) | B28: 0.1 | C28: =B28*$B$23 -> 625000
A29: Jimmy Christmas | B29: 0.03 | C29: =B29*$B$23 -> 187500
A30: Perry (optional) | B30: 0.03 | C30: =B30*$B$23 -> 187500
A31: Total | B31: =SUM(B25:B30) -> 1 | C31: =SUM(C25:C30) -> 6250000
A33: At a $6.25M exit: Repasch & Longley net ~$1.0M EACH; Michael ~$3.25M and KEEPS his 52% majority; Holt $625k; Jimmy/Perry $187k. All milestone-earned — nobody rides for free. Boys' slices come up to 16%; Holt/Perry come from Michael's share; Michael never drops below 51%.
A35: 4) UNITS TO EXIT — how many to sell to sell Amp Academy outright
A36: Target exit value ($) | B36: =$B$23 -> 6250000
A37: Price per unit ($) — edit me | B37: 99
A38: Buyer pays (× revenue) | B38: Revenue needed | C38: Units @ price | D38: … @ $199/yr | E38: … cohorts @ $4k/yr
A39: 10 | B39: =$B$36/A39 -> 625000 | C39: =B39/$B$37 -> 6313.1313 | D39: =B39/199 -> 3140.7035 | E39: =B39/4000 -> 156.25
A40: 5 | B40: =$B$36/A40 -> 1250000 | C40: =B40/$B$37 -> 12626.263 | D40: =B40/199 -> 6281.407 | E40: =B40/4000 -> 312.5
A41: 2.5 | B41: =$B$36/A41 -> 2500000 | C41: =B41/$B$37 -> 25252.525 | D41: =B41/199 -> 12562.814 | E41: =B41/4000 -> 625
A43: Read it: at a rich 10× a buyer needs only ~$625k of revenue (~6,300 course sales OR ~156 cohorts); at a thrifty 2.5× they want ~$2.5M (~25,300 sales OR ~625 cohorts). Higher multiple = fewer units to the same $6.25M exit. Recurring (subscription/cohort) revenue earns the higher multiples.
